<?xml version="1.0" encoding="utf-8"?>
<!-- This URDF was automatically created by SolidWorks to URDF Exporter! Originally created by Stephen Brawner (brawner@gmail.com) 
     Commit Version: 1.6.0-4-g7f85cfe  Build Version: 1.6.7995.38578
     For more information, please see http://wiki.ros.org/sw_urdf_exporter -->
<robot
  name="Ensamblajefullv6">
  <link name="world"/>
  <joint name="world_to_base" type="fixed">
    <parent link="world"/>
    <child link="base_link"/>
    <origin xyz="0 0 -1" rpy="-1.5708 0 0"/>
  </joint>
  <link
    name="base_link">
    <inertial>
      <origin
        xyz="0.012565 -0.015002 1.115"
        rpy="0 0 0" />
      <mass
        value="3" />
      <inertia
        ixx="0.007227"
        ixy="-9.6647E-18"
        ixz="-0.00067265"
        iyy="0.011719"
        iyz="-4.1083E-18"
        izz="0.014099" />
    </inertial>
    <visual>
      <origin
        xyz="0 0 0"
        rpy="0 0 0" />
      <geometry>
        <mesh
          filename="package://asse6/meshes/visual/base_link.STL" />
      </geometry>
      <material
        name="">
        <color
          rgba="0.79216 0.81961 0.93333 1" />
      </material>
    </visual>
    <collision>
      <origin
        xyz="0 0 0"
        rpy="0 0 0" />
      <geometry>
        <mesh
          filename="package://asse6/meshes/visual/base_link.STL" />
      </geometry>
    </collision>
  </link>
  <link
    name="BaseR">
    <inertial>
      <origin
        xyz="0.0078866 0.0026077 0.02651"
        rpy="0 0 0" />
      <mass
        value="0.25" />
      <inertia
        ixx="0.0011673"
        ixy="-1.5261E-05"
        ixz="-0.00011283"
        iyy="0.0012563"
        iyz="-2.409E-05"
        izz="0.0019548" />
    </inertial>
    <visual>
      <origin
        xyz="0 0 0"
        rpy="0 0 0" />
      <geometry>
        <mesh
          filename="package://asse6/meshes/visual/BaseR.STL" />
      </geometry>
      <material
        name="">
        <color
          rgba="0.79216 0.81961 0.93333 1" />
      </material>
    </visual>
    <collision>
      <origin
        xyz="0 0 0"
        rpy="0 0 0" />
      <geometry>
        <mesh
          filename="package://asse6/meshes/visual/BaseR.STL" />
      </geometry>
    </collision>
  </link>
  <joint
    name="R1"
    type="continuous">
    <origin
      xyz="-0.0541212640299427 -1.14500000000001 -0.0150018955467125"
      rpy="1.57079632679489 -1.56377472859413 0" />
    <parent
      link="base_link" />
    <child
      link="BaseR" />
    <axis
      xyz="0 0 1" />
  </joint>
  <link
    name="Arm1">
    <inertial>
      <origin
        xyz="-0.020414 -6.1851E-05 0.082682"
        rpy="0 0 0" />
      <mass
        value="0.15" />
      <inertia
        ixx="0.0010516"
        ixy="1.5848E-07"
        ixz="-1.1229E-05"
        iyy="0.00096052"
        iyz="1.6129E-07"
        izz="0.00013862" />
    </inertial>
    <visual>
      <origin
        xyz="0 0 0"
        rpy="0 0 0" />
      <geometry>
        <mesh
          filename="package://asse6/meshes/visual/Arm1.STL" />
      </geometry>
      <material
        name="">
        <color
          rgba="0.79216 0.81961 0.93333 1" />
      </material>
    </visual>
    <collision>
      <origin
        xyz="0 0 0"
        rpy="0 0 0" />
      <geometry>
        <mesh
          filename="package://asse6/meshes/visual/Arm1.STL" />
      </geometry>
    </collision>
  </link>
  <joint
    name="R2"
    type="continuous">
    <origin
      xyz="0.0400000000000003 0 0.0649999999999988"
      rpy="-0.470162054989727 0 1.5707963267949" />
    <parent
      link="BaseR" />
    <child
      link="Arm1" />
    <axis
      xyz="1 0 0" />
  </joint>
  <link
    name="Arm2">
    <inertial>
      <origin
        xyz="2.4367E-06 0.052614 0.02152"
        rpy="0 0 0" />
      <mass
        value="0.1" />
      <inertia
        ixx="0.00091559"
        ixy="-1.7395E-08"
        ixz="4.0709E-09"
        iyy="0.00015629"
        iyz="-4.3557E-05"
        izz="0.00095733" />
    </inertial>
    <visual>
      <origin
        xyz="0 0 0"
        rpy="0 0 0" />
      <geometry>
        <mesh
          filename="package://asse6/meshes/visual/Arm2.STL" />
      </geometry>
      <material
        name="">
        <color
          rgba="0.79216 0.81961 0.93333 1" />
      </material>
    </visual>
    <collision>
      <origin
        xyz="0 0 0"
        rpy="0 0 0" />
      <geometry>
        <mesh
          filename="package://asse6/meshes/visual/Arm2.STL" />
      </geometry>
    </collision>
  </link>
  <joint
    name="R3"
    type="continuous">
    <origin
      xyz="0 0 0.18"
      rpy="-1.5708 -1.0832 -1.5708" />
    <parent
      link="Arm1" />
    <child
      link="Arm2" />
    <axis
      xyz="0 0 1" />
  </joint>
</robot>